<?xml version="1.0" encoding="UTF-8"?>
<!-- Generated by org.testng.reporters.JUnitReportReporter -->
<testsuite hostname="HPDA0161" name="com.qait.automation.stik.test.TC_031" tests="9" failures="6" timestamp="18 Feb 2014 05:03:44 GMT" time="28.624" errors="1">
  <testcase name="H_Verify_Ui_Footer_Section" time="0.000" classname="com.qait.automation.stik.test.TC_031"/>
  <testcase name="D_Verify_Reviews_Section" time="0.000" classname="com.qait.automation.stik.test.TC_031"/>
  <testcase name="E_Verify_Referral_Section" time="0.000" classname="com.qait.automation.stik.test.TC_031"/>
  <testcase name="F_Verify_Stand_Out_Online_Section" time="0.001" classname="com.qait.automation.stik.test.TC_031"/>
  <testcase name="setup" time="6.826" classname="com.qait.automation.stik.test.TC_031"/>
  <testcase name="B_Navgiate_to_Feature_Page" time="9.058" classname="com.qait.automation.stik.test.TC_031">
    <error type="java.lang.AssertionError">
      <![CDATA[java.lang.AssertionError
	at com.qait.automation.stik.test.TC_031.B_Navgiate_to_Feature_Page(TC_031.java:39)
	at sun.reflect.NativeMethodAccessorImpl.invoke0(Native Method)
	at sun.reflect.NativeMethodAccessorImpl.invoke(Unknown Source)
	at sun.reflect.DelegatingMethodAccessorImpl.invoke(Unknown Source)
	at java.lang.reflect.Method.invoke(Unknown Source)
	at org.testng.internal.MethodInvocationHelper.invokeMethod(MethodInvocationHelper.java:80)
	at org.testng.internal.Invoker.invokeMethod(Invoker.java:714)
	at org.testng.internal.Invoker.invokeTestMethod(Invoker.java:901)
	at org.testng.internal.Invoker.invokeTestMethods(Invoker.java:1231)
	at org.testng.internal.TestMethodWorker.invokeTestMethods(TestMethodWorker.java:127)
	at org.testng.internal.TestMethodWorker.run(TestMethodWorker.java:111)
	at org.testng.TestRunner.privateRun(TestRunner.java:767)
	at org.testng.TestRunner.run(TestRunner.java:617)
	at org.testng.SuiteRunner.runTest(SuiteRunner.java:334)
	at org.testng.SuiteRunner.runSequentially(SuiteRunner.java:329)
	at org.testng.SuiteRunner.privateRun(SuiteRunner.java:291)
	at org.testng.SuiteRunner.run(SuiteRunner.java:240)
	at org.testng.SuiteRunnerWorker.runSuite(SuiteRunnerWorker.java:52)
	at org.testng.SuiteRunnerWorker.run(SuiteRunnerWorker.java:86)
	at org.testng.TestNG.runSuitesSequentially(TestNG.java:1197)
	at org.testng.TestNG.runSuitesLocally(TestNG.java:1122)
	at org.testng.TestNG.run(TestNG.java:1030)
	at org.testng.remote.RemoteTestNG.run(RemoteTestNG.java:111)
	at org.testng.remote.RemoteTestNG.initAndRun(RemoteTestNG.java:204)
	at org.testng.remote.RemoteTestNG.main(RemoteTestNG.java:175)
]]>
    </error>
  </testcase> <!-- B_Navgiate_to_Feature_Page -->
  <testcase name="G_Verify_ROI_Section" time="0.000" classname="com.qait.automation.stik.test.TC_031"/>
  <testcase name="A_launch_URL_Navgiate_to_Stick_HomePage" time="12.739" classname="com.qait.automation.stik.test.TC_031"/>
  <testcase name="C_Verify_Why_Stik_Section" time="0.000" classname="com.qait.automation.stik.test.TC_031"/>
</testsuite> <!-- com.qait.automation.stik.test.TC_031 -->
